Workbook

Sheet Parameters
A1: Refinery Cogeneration MILP — Parameter Sheet
A2: Legend: blue = input value (edit here) · black = formula · Basis column notes grounded vs representative
A4: 1. Steam Headers
A5: Parameter | B5: Value | C5: Unit | D5: Basis
A6: HP header pressure | B6: 45 | C6: bar | D6: Grounded — mid-range of 45-60 bar refinery HP practice
A7: MP header pressure | B7: 15 | C7: bar | D7: Grounded — mid-range of 12-17 bar
A8: LP header pressure | B8: 5 | C8: bar | D8: Grounded — mid-range of 4-6 bar
A9: HP steam enthalpy | B9: 2800 | C9: kJ/kg | D9: Grounded — standard steam tables, saturated ~45 bar
A10: MP steam enthalpy | B10: 2790 | C10: kJ/kg | D10: Grounded — standard steam tables, ~15 bar
A11: LP steam enthalpy | B11: 2750 | C11: kJ/kg | D11: Grounded — standard steam tables, ~5 bar
A13: 2. Boilers
A14: Parameter | B14: Value | C14: Unit | D14: Basis
A15: Number of boilers | B15: 2 | C15: count | D15: Derived — standard redundancy for mid-size refinery utility
A16: Capacity per boiler | B16: 60 | C16: t/h HP steam | D16: Derived/Scaled — sized with margin over demand profile
A17: Total boiler capacity | B17: =B15*B16 -> 120 | C17: t/h HP steam | D17: Formula = Number of boilers x Capacity per boiler
A18: Min-load (turndown) | B18: 0.3 | C18: fraction of capacity | D18: Grounded — typical industrial boiler turndown limit
A19: Boiler thermal efficiency | B19: 0.85 | C19: fraction | D19: Grounded — standard industrial boiler efficiency (85-90%)
A21: 3. Fuel
A22: Parameter | B22: Value | C22: Unit | D22: Basis
A23: Refinery fuel gas (RFG) calorific value | B23: 40 | C23: MJ/kg | D23: Grounded — mid-range of 35-45 MJ/kg from natural-gas-composition data
A24: Purchased natural gas price | B24: 37.5 | C24: Rs/kg | D24: Derived — representative Indian industrial PNG price range (35-40)
A25: Flaring penalty | B25: 5 | C25: Rs/kg RFG flared | D25: Derived — nominal penalty per project plan item 9
A27: 4. Turbine / Letdown
A28: Parameter | B28: Value | C28: Unit | D28: Basis
A29: Turbine max capacity | B29: 15 | C29: MW | D29: Derived/Scaled — sized against electricity demand profile
A30: Turbine steam rate (back-pressure) | B30: 8 | C30: kg steam / kWh | D30: Grounded — standard industrial back-pressure turbine range (6-10)
A32: 5. Electricity / Tariff (ToD)
A33: Parameter | B33: Value | C33: Unit | D33: Basis
A34: Grid base rate | B34: 4.5 | C34: Rs/kWh | D34: Grounded — IEX day-ahead avg Rs4.88 (Aug'26), Rs3.86 (FY26 avg); 4.5 is a defensible midpoint
A35: ToD peak multiplier (6-10 PM) | B35: 0.2 | C35: fraction above base | D35: Grounded — national ToD rule: peak +10-20%
A36: ToD solar/off-peak discount (10 AM-4 PM) | B36: 0.2 | C36: fraction below base | D36: Grounded — national ToD rule: solar hours -10-20%
A37: Peak rate | B37: =B34*(1+B35) -> 5.4 | C37: Rs/kWh | D37: Formula = base rate x (1 + peak multiplier)
A38: Solar/off-peak rate | B38: =B34*(1-B36) -> 3.6 | C38: Rs/kWh | D38: Formula = base rate x (1 - solar discount)
A39: Normal-hours rate | B39: =B34 -> 4.5 | C39: Rs/kWh | D39: Formula = base rate
A41: 6. Electricity Demand
A42: Parameter | B42: Value | C42: Unit | D42: Basis
A43: Plant electricity demand — baseline level | B43: 12 | C43: MW | D43: Derived/Scaled — flat-ish with mild daytime rise
A45: 7. Battery
A46: Parameter | B46: Value | C46: Unit | D46: Basis
A47: Battery capacity | B47: 5 | C47: MWh | D47: Derived/Scaled — carried over from existing project
...

Sheet Hourly_Profile
A1: 24-Hour Input Vectors
A2: All prices and demand values are formulas referencing Parameters — edit inputs there and this sheet recalculates.
A4: Hour (0-23) | B4: Tariff Band | C4: Electricity Price (Rs/kWh) | D4: HP Steam Demand (t/h) | E4: MP Steam Demand (t/h) | F4: LP Steam Demand (t/h) | G4: Electricity Demand (MW) | H4: RFG Availability (kg/h)
A5: 0 | B5: =IF(AND(A5>=18,A5<22),"Peak",IF(AND(A5>=10,A5<16),"Solar/Off-peak","Normal")) -> Normal | C5: =IF(B5="Peak",Parameters!$B$37,IF(B5="Solar/Off-peak",Parameters!$B$38,Parameters!$B$39)) -> 4.5 | D5: =(Parameters!$B$54+Parameters!$B$55)*(1+0.03*SIN((A5/24)*2*PI())) -> 55 | E5: =Parameters!$B$56*(1+0.05*SIN((A5/24)*2*PI()+1)) -> 20.841471 | F5: =Parameters!$B$57*(1+0.1*COS((A5-3)/24*2*PI())) -> 10.707107 | G5: =Parameters!$B$43*(1+0.08*SIN((A5-6)/24*2*PI())) -> 11.04 | H5: =1000*(1+0.2*SIN((A5/24)*2*PI()+2)) -> 1181.8595
A6: 1 | B6: =IF(AND(A6>=18,A6<22),"Peak",IF(AND(A6>=10,A6<16),"Solar/Off-peak","Normal")) -> Normal | C6: =IF(B6="Peak",Parameters!$B$37,IF(B6="Solar/Off-peak",Parameters!$B$38,Parameters!$B$39)) -> 4.5 | D6: =(Parameters!$B$54+Parameters!$B$55)*(1+0.03*SIN((A6/24)*2*PI())) -> 55.427051 | E6: =Parameters!$B$56*(1+0.05*SIN((A6/24)*2*PI()+1)) -> 20.952639 | F6: =Parameters!$B$57*(1+0.1*COS((A6-3)/24*2*PI())) -> 10.866025 | G6: =Parameters!$B$43*(1+0.08*SIN((A6-6)/24*2*PI())) -> 11.072711 | H6: =1000*(1+0.2*SIN((A6/24)*2*PI()+2)) -> 1154.1214
A7: 2 | B7: =IF(AND(A7>=18,A7<22),"Peak",IF(AND(A7>=10,A7<16),"Solar/Off-peak","Normal")) -> Normal | C7: =IF(B7="Peak",Parameters!$B$37,IF(B7="Solar/Off-peak",Parameters!$B$38,Parameters!$B$39)) -> 4.5 | D7: =(Parameters!$B$54+Parameters!$B$55)*(1+0.03*SIN((A7/24)*2*PI())) -> 55.825 | E7: =Parameters!$B$56*(1+0.05*SIN((A7/24)*2*PI()+1)) -> 20.998886 | F7: =Parameters!$B$57*(1+0.1*COS((A7-3)/24*2*PI())) -> 10.965926 | G7: =Parameters!$B$43*(1+0.08*SIN((A7-6)/24*2*PI())) -> 11.168616 | H7: =1000*(1+0.2*SIN((A7/24)*2*PI()+2)) -> 1115.8803
A8: 3 | B8: =IF(AND(A8>=18,A8<22),"Peak",IF(AND(A8>=10,A8<16),"Solar/Off-peak","Normal")) -> Normal | C8: =IF(B8="Peak",Parameters!$B$37,IF(B8="Solar/Off-peak",Parameters!$B$38,Parameters!$B$39)) -> 4.5 | D8: =(Parameters!$B$54+Parameters!$B$55)*(1+0.03*SIN((A8/24)*2*PI())) -> 56.166726 | E8: =Parameters!$B$56*(1+0.05*SIN((A8/24)*2*PI()+1)) -> 20.977061 | F8: =Parameters!$B$57*(1+0.1*COS((A8-3)/24*2*PI())) -> 11 | G8: =Parameters!$B$43*(1+0.08*SIN((A8-6)/24*2*PI())) -> 11.321177 | H8: =1000*(1+0.2*SIN((A8/24)*2*PI()+2)) -> 1069.742
A9: 4 | B9: =IF(AND(A9>=18,A9<22),"Peak",IF(AND(A9>=10,A9<16),"Solar/Off-peak","Normal")) -> Normal | C9: =IF(B9="Peak",Parameters!$B$37,IF(B9="Solar/Off-peak",Parameters!$B$38,Parameters!$B$39)) -> 4.5 | D9: =(Parameters!$B$54+Parameters!$B$55)*(1+0.03*SIN((A9/24)*2*PI())) -> 56.428942 | E9: =Parameters!$B$56*(1+0.05*SIN((A9/24)*2*PI()+1)) -> 20.888651 | F9: =Parameters!$B$57*(1+0.1*COS((A9-3)/24*2*PI())) -> 10.965926 | G9: =Parameters!$B$43*(1+0.08*SIN((A9-6)/24*2*PI())) -> 11.52 | H9: =1000*(1+0.2*SIN((A9/24)*2*PI()+2)) -> 1018.851
A10: 5 | B10: =IF(AND(A10>=18,A10<22),"Peak",IF(AND(A10>=10,A10<16),"Solar/Off-peak","Normal")) -> Normal | C10: =IF(B10="Peak",Parameters!$B$37,IF(B10="Solar/Off-peak",Parameters!$B$38,Parameters!$B$39)) -> 4.5 | D10: =(Parameters!$B$54+Parameters!$B$55)*(1+0.03*SIN((A10/24)*2*PI())) -> 56.593778 | E10: =Parameters!$B$56*(1+0.05*SIN((A10/24)*2*PI()+1)) -> 20.739681 | F10: =Parameters!$B$57*(1+0.1*COS((A10-3)/24*2*PI())) -> 10.866025 | G10: =Parameters!$B$43*(1+0.08*SIN((A10-6)/24*2*PI())) -> 11.751534 | H10: =1000*(1+0.2*SIN((A10/24)*2*PI()+2)) -> 966.6753
A11: 6 | B11: =IF(AND(A11>=18,A11<22),"Peak",IF(AND(A11>=10,A11<16),"Solar/Off-peak","Normal")) -> Normal | C11: =IF(B11="Peak",Parameters!$B$37,IF(B11="Solar/Off-peak",Parameters!$B$38,Parameters!$B$39)) -> 4.5 | D11: =(Parameters!$B$54+Parameters!$B$55)*(1+0.03*SIN((A11/24)*2*PI())) -> 56.65 | E11: =Parameters!$B$56*(1+0.05*SIN((A11/24)*2*PI()+1)) -> 20.540302 | F11: =Parameters!$B$57*(1+0.1*COS((A11-3)/24*2*PI())) -> 10.707107 | G11: =Parameters!$B$43*(1+0.08*SIN((A11-6)/24*2*PI())) -> 12 | H11: =1000*(1+0.2*SIN((A11/24)*2*PI()+2)) -> 916.77063
A12: 7 | B12: =IF(AND(A12>=18,A12<22),"Peak",IF(AND(A12>=10,A12<16),"Solar/Off-peak","Normal")) -> Normal | C12: =IF(B12="Peak",Parameters!$B$37,IF(B12="Solar/Off-peak",Parameters!$B$38,Parameters!$B$39)) -> 4.5 | D12: =(Parameters!$B$54+Parameters!$B$55)*(1+0.03*SIN((A12/24)*2*PI())) -> 56.593778 | E12: =Parameters!$B$56*(1+0.05*SIN((A12/24)*2*PI()+1)) -> 20.304103 | F12: =Parameters!$B$57*(1+0.1*COS((A12-3)/24*2*PI())) -> 10.5 | G12: =Parameters!$B$43*(1+0.08*SIN((A12-6)/24*2*PI())) -> 12.248466 | H12: =1000*(1+0.2*SIN((A12/24)*2*PI()+2)) -> 872.53791
A13: 8 | B13: =IF(AND(A13>=18,A13<22),"Peak",IF(AND(A13>=10,A13<16),"Solar/Off-peak","Normal")) -> Normal | C13: =IF(B13="Peak",Parameters!$B$37,IF(B13="Solar/Off-peak",Parameters!$B$38,Parameters!$B$39)) -> 4.5 | D13: =(Parameters!$B$54+Parameters!$B$55)*(1+0.03*SIN((A13/24)*2*PI())) -> 56.428942 | E13: =Parameters!$B$56*(1+0.05*SIN((A13/24)*2*PI()+1)) -> 20.04718 | F13: =Parameters!$B$57*(1+0.1*COS((A13-3)/24*2*PI())) -> 10.258819 | G13: =Parameters!$B$43*(1+0.08*SIN((A13-6)/24*2*PI())) -> 12.48 | H13: =1000*(1+0.2*SIN((A13/24)*2*PI()+2)) -> 836.99151
A14: 9 | B14: =IF(AND(A14>=18,A14<22),"Peak",IF(AND(A14>=10,A14<16),"Solar/Off-peak","Normal")) -> Normal | C14: =IF(B14="Peak",Parameters!$B$37,IF(B14="Solar/Off-peak",Parameters!$B$38,Parameters!$B$39)) -> 4.5 | D14: =(Parameters!$B$54+Parameters!$B$55)*(1+0.03*SIN((A14/24)*2*PI())) -> 56.166726 | E14: =Parameters!$B$56*(1+0.05*SIN((A14/24)*2*PI()+1)) -> 19.787042 | F14: =Parameters!$B$57*(1+0.1*COS((A14-3)/24*2*PI())) -> 10 | G14: =Parameters!$B$43*(1+0.08*SIN((A14-6)/24*2*PI())) -> 12.678823 | H14: =1000*(1+0.2*SIN((A14/24)*2*PI()+2)) -> 812.55387
A15: 10 | B15: =IF(AND(A15>=18,A15<22),"Peak",IF(AND(A15>=10,A15<16),"Solar/Off-peak","Normal")) -> Solar/Off-peak | C15: =IF(B15="Peak",Parameters!$B$37,IF(B15="Solar/Off-peak",Parameters!$B$38,Parameters!$B$39)) -> 3.6 | D15: =(Parameters!$B$54+Parameters!$B$55)*(1+0.03*SIN((A15/24)*2*PI())) -> 55.825 | E15: =Parameters!$B$56*(1+0.05*SIN((A15/24)*2*PI()+1)) -> 19.541416 | F15: =Parameters!$B$57*(1+0.1*COS((A15-3)/24*2*PI())) -> 9.741181 | G15: =Parameters!$B$43*(1+0.08*SIN((A15-6)/24*2*PI())) -> 12.831384 | H15: =1000*(1+0.2*SIN((A15/24)*2*PI()+2)) -> 800.89038
A16: 11 | B16: =IF(AND(A16>=18,A16<22),"Peak",IF(AND(A16>=10,A16<16),"Solar/Off-peak","Normal")) -> Solar/Off-peak | C16: =IF(B16="Peak",Parameters!$B$37,IF(B16="Solar/Off-peak",Parameters!$B$38,Parameters!$B$39)) -> 3.6 | D16: =(Parameters!$B$54+Parameters!$B$55)*(1+0.03*SIN((A16/24)*2*PI())) -> 55.427051 | E16: =Parameters!$B$56*(1+0.05*SIN((A16/24)*2*PI()+1)) -> 19.327042 | F16: =Parameters!$B$57*(1+0.1*COS((A16-3)/24*2*PI())) -> 9.5 | G16: =Parameters!$B$43*(1+0.08*SIN((A16-6)/24*2*PI())) -> 12.927289 | H16: =1000*(1+0.2*SIN((A16/24)*2*PI()+2)) -> 802.79588
... A28: 23 | B28: =IF(AND(A28>=18,A28<22),"Peak",IF(AND(A28>=10,A28<16),"Solar/Off-peak","Normal")) -> Normal | C28: =IF(B28="Peak",Parameters!$B$37,IF(B28="Solar/Off-peak",Parameters!$B$38,Parameters!$B$39)) -> 4.5 | D28: =(Parameters!$B$54+Parameters!$B$55)*(1+0.03*SIN((A28/24)*2*PI())) -> 54.572949 | E28: =Parameters!$B$56*(1+0.05*SIN((A28/24)*2*PI()+1)) -> 20.672958 | F28: =Parameters!$B$57*(1+0.1*COS((A28-3)/24*2*PI())) -> 10.5 | G28: =Parameters!$B$43*(1+0.08*SIN((A28-6)/24*2*PI())) -> 11.072711 | H28: =1000*(1+0.2*SIN((A28/24)*2*PI()+2)) -> 1197.2041
A30: Daily avg | C30: =AVERAGE(C5:C28) -> 4.425 | D30: =AVERAGE(D5:D28) -> 55 | E30: =AVERAGE(E5:E28) -> 20 | F30: =AVERAGE(F5:F28) -> 10 | G30: =AVERAGE(G5:G28) -> 12 | H30: =AVERAGE(H5:H28) -> 1000

Sheet Notes & Sources
A1: Notes, Assumptions & Sources
A3: Grounded values
A4: Sourced from real industry data: refinery steam header pressure ranges, natural gas/RFG calorific value ranges, Indian ToD tariff structure (national rule: peak +10-20%, solar hours -10-20%), and IEX day-ahead/real-time market clearing prices (Aug 2026 / FY26 averages).
A6: Derived/Scaled values
A7: Boiler count/capacity, turbine capacity, electricity demand level, and battery specs are sized to be internally consistent with the grounded numbers (e.g., boiler capacity comfortably covers total steam demand). These are NOT sourced from a specific real refinery.
A9: Steam demand components
A10: HP/MP/LP demand is built from representative named consumers (CDU, hydrocracker, hydrotreater, tank heating) rather than one anonymous number, to reflect typical refinery steam end-uses. Exact real-plant demand data is proprietary and was not used.
A12: Do not claim
A13: This model should not be presented as calibrated to, or validated against, any specific named refinery. It should also not be directly compared numerically against savings percentages reported in other published studies (e.g., sugar-mill cogeneration papers) — those used different plant scale, currency, and fuel mix.
A15: Tariff bands used
A16: Peak: 18:00-22:00 (+20% of base). Solar/off-peak: 10:00-16:00 (-20% of base). Normal: all other hours (base rate). Matches the national ToD framework structure; exact state/DISCOM windows vary and should be cited as representative.
A18: Next steps
A19: Use Hourly_Profile columns C-H as the input vectors for the MATLAB baseline script and, later, the MILP (intlinprog). Parameters sheet is the single source of truth — update values there only.
